Workbook

Sheet Read me
A1: DVS Gesture SNN — Hyperparameter Search: Statistical Analysis
A3: What this analyzes
A4: Two Optuna/Ray searches over the HiAER-Spike-constrained DVS Gesture model. • RUN B (uniform space): 50 trials, 35 feasible. Plain BatchNorm on/off, one geometry for all layers. The successful run (best 87.5%). • RUN A (per-layer space): 15 trials, 6 feasible. Adds tdBN, learnable tau/threshold, independent per-layer geometry. The struggling run.
A6: Outcome analyzed
A7: best_val = best validation accuracy the trial reached. Feasibility = passes the 5 HiAER-Spike axon/fan-in/fan-out limits (a static check, before any training).
A9: Tests used, and why
A10: • Feasibility (categorical outcome) vs each knob -> chi-square with Cramer's V effect size. Fisher's exact where cells are small. • best_val is NON-normal and bimodal (Shapiro-Wilk W=0.80, p=1.8e-5) — a dead cluster near chance plus a spread of learners — so PARAMETRIC t-tests are invalid. Nonparametric throughout: – binary knob vs accuracy -> Mann-Whitney U, effect size = rank-biserial r – multi-level knob vs accuracy -> Kruskal-Wallis H, effect size = epsilon-squared – continuous knob vs accuracy -> Spearman rank correlation rho (rho IS the effect size) • 15 knobs tested at once -> Benjamini-Hochberg FDR correction; report q (p_fdr). Significant = q < 0.05. • Headline normalization effect pooled across both runs (RUN A norm!=none == on; RUN B batchnorm==on) -> Mann-Whitney + Fisher's exact on learned/dead.
A12: The findings (all FDR-corrected)
A13: 1. NORMALIZATION IS MANDATORY. With it: median 0.73. Without it: median 0.07 (below chance). Pooled Mann-Whitney p=0.0015 (r=0.67); learned-vs-dead odds ratio 21.8, Fisher p=0.001. Every dead network lacked normalization. 2. WIDTH drives INFEASIBILITY. channels is the only significant feasibility driver (chi-square p=0.0006, V=0.59): 32ch 88% feasible, 128ch 14%, 256ch 50%. Wide nets bust fan-in/fan-out. 3. LOW tau helps. Spearman rho=-0.60 (q=0.002) — winners cluster at tau~1.5-1.9. 4. FEWER FC layers help. Kruskal-Wallis q=0.044; every top model has 0 hidden FC (encoder straight to classifier). 5. Higher lr (q=0.044, within 1e-4..5e-3) and lower weight_decay (rho=-0.47, q=0.020) help. 6. NOT significant after FDR: resize, downsample mode, dropout, label smoothing, optimizer, kernel, depth, T (T=16 favoured but only p=0.10).
A15: What it means for the search space
A16: • DELETE norm=none / batchnorm=false — it produced every dead trial and wasted ~1/4 of the budget. • CONSTRAIN channels to {32, 64} — 128/256 are mostly infeasible and never better. • NARROW tau to ~[1.5, 2.5], bias fc_layers to {0, 1}, keep lr toward the high end, weight_decay low. • These five changes would let a ~20-trial rerun spend nearly all of its budget on models that actually train.
A18: What it means for the model
... A22: • SMALL n. RUN B feasible n=35 (exploratory, hypothesis-generating, not confirmatory); RUN A feasible n=6 has essentially no power — its tdBN/learnable-neuron trials are DESCRIPTIVE ONLY and fully confounded with norm=none. • ASHA CENSORING. Pruned trials stopped at 8 or 24 epochs, so their best_val is a floor, biased low. The dead (norm-off) trials are genuinely flat at epoch 8, so that effect is real; but tau/lr correlations may be partly censoring-driven. • OBSERVATIONAL, not randomized. TPE concentrates sampling on good regions, so winning knobs are correlated (low tau + BN + 32ch co-occur). Single-knob effects cannot be fully separated. A controlled A/B (freeze the winner, vary one knob) is the clean follow-up — especially for tdBN and learnable neurons, which this data cannot judge.

Sheet Trial data
A1: run | B1: trial_id | C1: feasible | D1: feas01 | E1: best_val | F1: learned01 | G1: epochs_run | H1: stopped_early | I1: neurons | J1: params | K1: connections | L1: depth | M1: channels | N1: kernel_size | O1: downsample_mode | P1: stride | Q1: resize_to | R1: T | S1: tau | T1: fc_layers | U1: final_reduction | V1: dropout_rate | W1: label_smoothing | X1: grad_clip | Y1: optimizer | Z1: lr | AA1: weight_decay | AB1: scheduler | AC1: norm | AD1: norm_kind | AE1: norm_present | AF1: tdbn_alpha | AG1: trainable_tau | AH1: trainable_threshold
A2: A_per_layer | B2: 6ecd9b62 | C2: =TRUE() -> TRUE | D2: 1 | E2: 0.34090909 | F2: 1 | G2: 40 | H2: =FALSE() -> FALSE | I2: 577547 | J2: 856704 | K2: 313023104 | L2: 5 | Q2: 64 | R2: 16 | S2: 3.750965 | T2: 1 | U2: gap | V2: 0.030928488 | W2: 0.011976805 | X2: 0 | Y2: adam | Z2: 0.0044075704 | AA2: 8.869736e-08 | AB2: step | AC2: tdbn | AD2: tdbn | AE2: =TRUE() -> TRUE | AF2: 1.6516827 | AG2: =FALSE() -> FALSE | AH2: =FALSE() -> FALSE
A3: A_per_layer | B3: 469238c4 | C3: =FALSE() -> FALSE | D3: 0 | F3: 0 | G3: 0 | H3: =FALSE() -> FALSE | L3: 5 | Q3: 64 | R3: 8 | S3: 1.6343086 | T3: 3 | U3: flatten | V3: 0.15298739 | W3: 0.0039998382 | X3: 0 | Y3: adam | Z3: 0.00061852031 | AA3: 7.5748317e-07 | AB3: cosine | AC3: none | AD3: none | AE3: =FALSE() -> FALSE | AG3: =TRUE() -> TRUE | AH3: =TRUE() -> TRUE
A4: A_per_layer | B4: 39a15454 | C4: =TRUE() -> TRUE | D4: 1 | E4: 0.21022727 | F4: 1 | G4: 8 | H4: =TRUE() -> TRUE | I4: 927883 | J4: 5538112 | K4: 1531883008 | L4: 3 | Q4: 64 | R4: 8 | S4: 3.3436941 | T4: 3 | U4: flatten | V4: 0.39615202 | W4: 0.00090997393 | X4: 5 | Y4: adamw | Z4: 0.0024240065 | AA4: 0.066900216 | AB4: cosine | AC4: bn | AD4: bn | AE4: =TRUE() -> TRUE | AG4: =FALSE() -> FALSE | AH4: =FALSE() -> FALSE
A5: A_per_layer | B5: 6841f40c | C5: =TRUE() -> TRUE | D5: 1 | E5: 0.068181818 | F5: 0 | G5: 8 | H5: =TRUE() -> TRUE | I5: 614923 | J5: 155584 | K5: 116778880 | L5: 3 | Q5: 64 | R5: 16 | S5: 3.9468815 | T5: 0 | U5: gap | V5: 0.16341926 | W5: 0.052095018 | X5: 0 | Y5: adam | Z5: 0.00015993867 | AA5: 1.3550301e-06 | AB5: cosine | AC5: none | AD5: none | AE5: =FALSE() -> FALSE | AG5: =TRUE() -> TRUE | AH5: =TRUE() -> TRUE
A6: A_per_layer | B6: f49ab8be | C6: =FALSE() -> FALSE | D6: 0 | F6: 0 | G6: 0 | H6: =FALSE() -> FALSE | L6: 4 | Q6: 32 | R6: 16 | S6: 3.4366319 | T6: 3 | U6: flatten | V6: 0.15851133 | W6: 0.14095546 | X6: 1 | Y6: adamw | Z6: 0.00022101785 | AA6: 0.036927258 | AB6: none | AC6: tdbn | AD6: tdbn | AE6: =TRUE() -> TRUE | AF6: 1.8303403 | AG6: =TRUE() -> TRUE | AH6: =FALSE() -> FALSE
A7: A_per_layer | B7: 06a415d0 | C7: =TRUE() -> TRUE | D7: 1 | E7: 0.068181818 | F7: 0 | G7: 8 | H7: =TRUE() -> TRUE | I7: 24939 | J7: 264512 | K7: 10714048 | L7: 3 | Q7: 32 | R7: 16 | S7: 2.434947 | T7: 2 | U7: flatten | V7: 0.55804612 | W7: 0.13550975 | X7: 1 | Y7: adam | Z7: 0.0036731611 | AA7: 0.00020188404 | AB7: onecycle | AC7: tdbn | AD7: tdbn | AE7: =TRUE() -> TRUE | AF7: 1.3269127 | AG7: =FALSE() -> FALSE | AH7: =FALSE() -> FALSE
A8: A_per_layer | B8: f0421abc | C8: =TRUE() -> TRUE | D8: 1 | E8: 0.068181818 | F8: 0 | G8: 8 | H8: =TRUE() -> TRUE | I8: 142667 | J8: 2050272 | K8: 24706560 | L8: 4 | Q8: 32 | R8: 16 | S8: 3.3595656 | T8: 1 | U8: flatten | V8: 0.38075656 | W8: 0.035961646 | X8: 0 | Y8: adamw | Z8: 0.00073811279 | AA8: 0.0016370314 | AB8: onecycle | AC8: none | AD8: none | AE8: =FALSE() -> FALSE | AG8: =TRUE() -> TRUE | AH8: =FALSE() -> FALSE
A9: A_per_layer | B9: 8e346be1 | C9: =FALSE() -> FALSE | D9: 0 | F9: 0 | G9: 0 | H9: =FALSE() -> FALSE | L9: 3 | Q9: 32 | R9: 8 | S9: 1.6904953 | T9: 3 | U9: gap | V9: 0.56480855 | W9: 0.14547732 | X9: 5 | Y9: adam | Z9: 0.003843619 | AA9: 8.524829e-07 | AB9: onecycle | AC9: none | AD9: none | AE9: =FALSE() -> FALSE | AG9: =TRUE() -> TRUE | AH9: =FALSE() -> FALSE
A10: A_per_layer | B10: 5ccc6c8a | C10: =FALSE() -> FALSE | D10: 0 | F10: 0 | G10: 0 | H10: =FALSE() -> FALSE | L10: 3 | Q10: 64 | R10: 8 | S10: 1.6289095 | T10: 2 | U10: gap | V10: 0.31947282 | W10: 0.13574523 | X10: 0 | Y10: adamw | Z10: 0.0017539679 | AA10: 0.0003579136 | AB10: none | AC10: none | AD10: none | AE10: =FALSE() -> FALSE | AG10: =TRUE() -> TRUE | AH10: =TRUE() -> TRUE
A11: A_per_layer | B11: d5ed0c14 | C11: =FALSE() -> FALSE | D11: 0 | F11: 0 | G11: 0 | H11: =FALSE() -> FALSE | L11: 3 | Q11: 64 | R11: 8 | S11: 2.0349313 | T11: 0 | U11: gap | V11: 0.333826 | W11: 0.088917393 | X11: 1 | Y11: adam | Z11: 0.0047157149 | AA11: 1.7512804e-05 | AB11: onecycle | AC11: tdbn | AD11: tdbn | AE11: =TRUE() -> TRUE | AF11: 1.9010477 | AG11: =FALSE() -> FALSE | AH11: =FALSE() -> FALSE
A12: A_per_layer | B12: 0651222d | C12: =FALSE() -> FALSE | D12: 0 | F12: 0 | G12: 0 | H12: =FALSE() -> FALSE | L12: 2 | Q12: 64 | R12: 16 | S12: 2.4723071 | T12: 0 | U12: flatten | V12: 0.55918426 | W12: 0.11561503 | X12: 1 | Y12: adam | Z12: 0.0010634767 | AA12: 1.5292855e-06 | AB12: step | AC12: bn | AD12: bn | AE12: =TRUE() -> TRUE | AG12: =FALSE() -> FALSE | AH12: =TRUE() -> TRUE
A13: A_per_layer | B13: 608c27b6 | C13: =TRUE() -> TRUE | D13: 1 | E13: 0.068181818 | F13: 0 | G13: 8 | H13: =TRUE() -> TRUE | I13: 446987 | J13: 221312 | K13: 634055936 | L13: 2 | Q13: 64 | R13: 16 | S13: 2.6667561 | T13: 1 | U13: gap | V13: 0.01448334 | W13: 0.19524966 | X13: 0 | Y13: adam | Z13: 0.0001007937 | AA13: 2.0489483e-08 | AB13: step | AC13: bn | AD13: bn | AE13: =TRUE() -> TRUE | AG13: =FALSE() -> FALSE | AH13: =TRUE() -> TRUE
A14: A_per_layer | B14: 0b06e134 | C14: =FALSE() -> FALSE | D14: 0 | F14: 0 | G14: 0 | H14: =FALSE() -> FALSE | L14: 5 | Q14: 64 | R14: 8 | S14: 3.4176663 | T14: 1 | U14: gap | V14: 0.070907014 | W14: 0.005720984 | X14: 5 | Y14: adamw | Z14: 0.001920263 | AA14: 0.099092921 | AB14: step | AC14: bn | AD14: bn | AE14: =TRUE() -> TRUE | AG14: =FALSE() -> FALSE | AH14: =FALSE() -> FALSE
A15: A_per_layer | B15: f2dfc25f | C15: =FALSE() -> FALSE | D15: 0 | F15: 0 | G15: 0 | H15: =FALSE() -> FALSE | L15: 5 | Q15: 64 | R15: 8 | S15: 3.3746596 | T15: 2 | U15: flatten | V15: 0.016252608 | W15: 0.0026865086 | X15: 5 | Y15: adamw | Z15: 0.0020760141 | AA15: 0.050913945 | AB15: step | AC15: bn | AD15: bn | AE15: =TRUE() -> TRUE | AG15: =FALSE() -> FALSE | AH15: =FALSE() -> FALSE
A16: A_per_layer | B16: 78a86e6c | C16: =FALSE() -> FALSE | D16: 0 | F16: 0 | G16: 0 | H16: =FALSE() -> FALSE | L16: 4 | Q16: 64 | R16: 8 | S16: 3.7939009 | T16: 2 | U16: flatten | V16: 0.4451099 | W16: 0.039413817 | X16: 5 | Y16: adamw | Z16: 0.0022745977 | AA16: 0.0055101058 | AB16: cosine | AC16: bn | AD16: bn | AE16: =TRUE() -> TRUE | AG16: =FALSE() -> FALSE | AH16: =FALSE() -> FALSE
A17: B_uniform | B17: 93b686f1 | C17: =TRUE() -> TRUE | D17: 1 | E17: 0.34659091 | F17: 1 | G17: 40 | H17: =FALSE() -> FALSE | I17: 57035 | J17: 3332032 | K17: 45148864 | L17: 3 | M17: 256 | N17: 5 | O17: stride | P17: 2 | Q17: 32 | R17: 8 | S17: 2.6323306 | T17: 2 | U17: flatten | V17: 0.2870993 | W17: 0.16378361 | X17: 1 | Y17: adamw | Z17: 0.00065681729 | AA17: 2.4818805e-06 | AB17: cosine | AD17: none | AE17: =FALSE() -> FALSE
A18: B_uniform | B18: c375c98b | C18: =TRUE() -> TRUE | D18: 1 | E18: 0.67613636 | F18: 1 | G18: 40 | H18: =FALSE() -> FALSE | I18: 140171 | J18: 1237376 | K18: 85633408 | L18: 3 | M18: 128 | N18: 5 | O18: stride | P18: 2 | Q18: 64 | R18: 8 | S18: 2.5005641 | T18: 1 | U18: flatten | V18: 0.5941272 | W18: 0.043188412 | X18: 1 | Y18: adam | Z18: 0.0013820217 | AA18: 0.00016390913 | AB18: none | AD18: bn | AE18: =TRUE() -> TRUE
A19: B_uniform | B19: e1eed3f4 | C19: =FALSE() -> FALSE | D19: 0 | F19: 0 | G19: 0 | H19: =FALSE() -> FALSE | L19: 2 | M19: 128 | N19: 3 | O19: pool | Q19: 32 | R19: 8 | S19: 1.6883248 | T19: 0 | U19: flatten | V19: 0.31121724 | W19: 0.0067349752 | X19: 5 | Y19: adam | Z19: 0.00017059117 | AA19: 0.00016326905 | AB19: step | AD19: bn | AE19: =TRUE() -> TRUE
A20: B_uniform | B20: e0db2881 | C20: =FALSE() -> FALSE | D20: 0 | F20: 0 | G20: 0 | H20: =FALSE() -> FALSE | L20: 2 | M20: 128 | N20: 5 | O20: pool | Q20: 32 | R20: 8 | S20: 3.476722 | T20: 3 | U20: flatten | V20: 0.33012458 | W20: 0.072724502 | X20: 1 | Y20: adamw | Z20: 0.002721337 | AA20: 1.5458387e-05 | AB20: none | AD20: bn | AE20: =TRUE() -> TRUE
A21: B_uniform | B21: dc0cbc39 | C21: =TRUE() -> TRUE | D21: 1 | E21: 0.14204545 | F21: 1 | G21: 8 | H21: =TRUE() -> TRUE | I21: 43787 | J21: 122112 | K21: 10403712 | L21: 5 | M21: 32 | N21: 5 | O21: pool | Q21: 32 | R21: 16 | S21: 3.9775545 | T21: 1 | U21: flatten | V21: 0.0091039158 | W21: 0.17258841 | X21: 1 | Y21: adamw | Z21: 0.0014322973 | AA21: 0.031381476 | AB21: onecycle | AD21: bn | AE21: =TRUE() -> TRUE
A22: B_uniform | B22: 265d27e5 | C22: =FALSE() -> FALSE | D22: 0 | F22: 0 | G22: 0 | H22: =FALSE() -> FALSE | L22: 2 | M22: 128 | N22: 7 | O22: stride | P22: 1 | Q22: 32 | R22: 8 | S22: 2.7489982 | T22: 2 | U22: flatten | V22: 0.51774228 | W22: 0.13978919 | X22: 5 | Y22: adamw | Z22: 0.0018233703 | AA22: 9.8685316e-06 | AB22: cosine | AD22: bn | AE22: =TRUE() -> TRUE
A23: B_uniform | B23: dc4a143e | C23: =TRUE() -> TRUE | D23: 1 | E23: 0.6875 | F23: 1 | G23: 40 | H23: =FALSE() -> FALSE | I23: 344395 | J23: 489728 | K23: 144804608 | L23: 3 | M23: 64 | N23: 5 | O23: pool | Q23: 64 | R23: 8 | S23: 1.6644899 | T23: 2 | U23: flatten | V23: 0.36735647 | W23: 0.002165416 | X23: 0 | Y23: adamw | Z23: 0.00038510991 | AA23: 7.562335e-05 | AB23: step | AD23: bn | AE23: =TRUE() -> TRUE
A24: B_uniform | B24: 1d811f3a | C24: =TRUE() -> TRUE | D24: 1 | E24: 0.068181818 | F24: 0 | G24: 8 | H24: =TRUE() -> TRUE | I24: 18827 | J24: 247808 | K24: 2570048 | L24: 3 | M24: 64 | N24: 3 | O24: stride | P24: 2 | Q24: 32 | R24: 16 | S24: 2.7851009 | T24: 3 | U24: flatten | V24: 0.54250385 | W24: 0.08213661 | X24: 5 | Y24: adam | Z24: 0.00015740517 | AA24: 3.4252461e-05 | AB24: cosine | AD24: none | AE24: =FALSE() -> FALSE
A25: B_uniform | B25: 69bce916 | C25: =TRUE() -> TRUE | D25: 1 | E25: 0.068181818 | F25: 0 | G25: 8 | H25: =TRUE() -> TRUE | I25: 348939 | J25: 510848 | K25: 55010816 | L25: 4 | M25: 64 | N25: 3 | O25: pool | Q25: 64 | R25: 16 | S25: 2.5429572 | T25: 2 | U25: flatten | V25: 0.52326606 | W25: 0.046598693 | X25: 5 | Y25: adamw | Z25: 0.0039903305 | AA25: 0.0023941675 | AB25: cosine | AD25: none | AE25: =FALSE() -> FALSE
A26: B_uniform | B26: 3626799c | C26: =FALSE() -> FALSE | D26: 0 | F26: 0 | G26: 0 | H26: =FALSE() -> FALSE | L26: 2 | M26: 64 | N26: 5 | O26: pool | Q26: 64 | R26: 8 | S26: 3.1838861 | T26: 1 | U26: flatten | V26: 0.016566077 | W26: 0.14672561 | X26: 0 | Y26: adam | Z26: 0.00010614046 | AA26: 2.1944891e-05 | AB26: none | AD26: none | AE26: =FALSE() -> FALSE
A27: B_uniform | B27: a89c83db | C27: =FALSE() -> FALSE | D27: 0 | F27: 0 | G27: 0 | H27: =FALSE() -> FALSE | L27: 5 | M27: 128 | N27: 7 | O27: pool | Q27: 64 | R27: 8 | S27: 2.0112206 | T27: 0 | U27: flatten | V27: 0.51504905 | W27: 0.10624209 | X27: 5 | Y27: adam | Z27: 0.00014674842 | AA27: 0.00012043047 | AB27: cosine | AD27: bn | AE27: =TRUE() -> TRUE
A28: B_uniform | B28: 2e781a0d | C28: =TRUE() -> TRUE | D28: 1 | E28: 0.76704545 | F28: 1 | G28: 40 | H28: =FALSE() -> FALSE | I28: 32395 | J28: 207328 | K28: 11220640 | L28: 5 | M28: 32 | N28: 7 | O28: stride | P28: 2 | Q28: 64 | R28: 16 | S28: 2.1384804 | T28: 0 | U28: flatten | V28: 0.12730304 | W28: 0.19864285 | X28: 1 | Y28: adam | Z28: 0.00062530663 | AA28: 2.2830483e-08 | AB28: none | AD28: bn | AE28: =TRUE() -> TRUE
A29: B_uniform | B29: 57606a00 | C29: =TRUE() -> TRUE | D29: 1 | E29: 0.76704545 | F29: 1 | G29: 40 | H29: =FALSE() -> FALSE | I29: 280587 | J29: 6573568 | K29: 332652032 | L29: 3 | M29: 256 | N29: 5 | O29: stride | P29: 2 | Q29: 64 | R29: 8 | S29: 1.5251599 | T29: 1 | U29: flatten | V29: 0.40869334 | W29: 2.3305713e-05 | X29: 0 | Y29: adam | Z29: 0.00069280343 | AA29: 2.12154e-08 | AB29: step | AD29: bn | AE29: =TRUE() -> TRUE
A30: B_uniform | B30: f71edc30 | C30: =TRUE() -> TRUE | D30: 1 | E30: 0.77840909 | F30: 1 | G30: 40 | H30: =FALSE() -> FALSE | I30: 32619 | J30: 307008 | K30: 10918976 | L30: 4 | M30: 32 | N30: 7 | O30: stride | P30: 2 | Q30: 64 | R30: 16 | S30: 2.0782954 | T30: 1 | U30: flatten | V30: 0.15794363 | W30: 0.18635455 | X30: 1 | Y30: adam | Z30: 0.00078790479 | AA30: 2.6498352e-08 | AB30: none | AD30: bn | AE30: =TRUE() -> TRUE
A31: B_uniform | B31: 0e62ca7a | C31: =FALSE() -> FALSE | D31: 0 | F31: 0 | G31: 0 | H31: =FALSE() -> FALSE | L31: 4 | M31: 256 | N31: 7 | O31: stride | P31: 2 | Q31: 64 | R31: 16 | S31: 2.0449165 | T31: 0 | U31: flatten | V31: 0.15110168 | W31: 0.1980832 | X31: 0 | Y31: adam | Z31: 0.00057906418 | AA31: 1.4595173e-08 | AB31: step | AD31: bn | AE31: =TRUE() -> TRUE
A32: B_uniform | B32: 2ed40450 | C32: =FALSE() -> FALSE | D32: 0 | F32: 0 | G32: 0 | H32: =FALSE() -> FALSE | L32: 4 | M32: 256 | N32: 7 | O32: stride | P32: 2 | Q32: 64 | R32: 16 | S32: 2.0715874 | T32: 0 | U32: flatten | V32: 0.13381636 | W32: 0.11403795 | X32: 0 | Y32: adam | Z32: 0.00038411378 | AA32: 1.0933729e-08 | AB32: step | AD32: bn | AE32: =TRUE() -> TRUE
A33: B_uniform | B33: 7919e0d7 | C33: =FALSE() -> FALSE | D33: 0 | F33: 0 | G33: 0 | H33: =FALSE() -> FALSE | L33: 5 | M33: 256 | N33: 7 | O33: stride | P33: 1 | Q33: 64 | R33: 16 | S33: 1.5891506 | T33: 0 | U33: flatten | V33: 0.1885746 | W33: 0.11854807 | X33: 0 | Y33: adam | Z33: 0.00032756508 | AA33: 9.5350794e-08 | AB33: onecycle | AD33: bn | AE33: =TRUE() -> TRUE
A34: B_uniform | B34: 21b7d73f | C34: =FALSE() -> FALSE | D34: 0 | F34: 0 | G34: 0 | H34: =FALSE() -> FALSE | L34: 5 | M34: 32 | N34: 7 | O34: stride | P34: 1 | Q34: 64 | R34: 16 | S34: 1.5475851 | T34: 1 | U34: flatten | V34: 0.4462108 | W34: 0.032261324 | X34: 0 | Y34: adam | Z34: 0.00033750086 | AA34: 1.0771777e-07 | AB34: onecycle | AD34: bn | AE34: =TRUE() -> TRUE
A35: B_uniform | B35: bb4cd8d1 | C35: =TRUE() -> TRUE | D35: 1 | E35: 0.35227273 | F35: 1 | G35: 8 | H35: =TRUE() -> TRUE | I35: 35595 | J35: 126336 | K35: 6479616 | L35: 5 | M35: 32 | N35: 5 | O35: stride | P35: 2 | Q35: 64 | R35: 16 | S35: 1.8427643 | T35: 1 | U35: flatten | V35: 0.44695124 | W35: 0.041573268 | X35: 0 | Y35: adam | Z35: 0.00096680391 | AA35: 2.1447966e-07 | AB35: none | AD35: bn | AE35: =TRUE() -> TRUE
A36: B_uniform | B36: d591e590 | C36: =TRUE() -> TRUE | D36: 1 | E36: 0.068181818 | F36: 0 | G36: 8 | H36: =TRUE() -> TRUE | I36: 36075 | J36: 122560 | K36: 6476032 | L36: 4 | M36: 32 | N36: 5 | O36: stride | P36: 2 | Q36: 64 | R36: 8 | S36: 2.3439249 | T36: 1 | U36: flatten | V36: 0.41871341 | W36: 0.080936674 | X36: 1 | Y36: adam | Z36: 0.00093243575 | AA36: 3.9004574e-07 | AB36: step | AD36: none | AE36: =FALSE() -> FALSE
A37: B_uniform | B37: 88d6f97e | C37: =TRUE() -> TRUE | D37: 1 | E37: 0.068181818 | F37: 0 | G37: 8 | H37: =TRUE() -> TRUE | I37: 318475 | J37: 1800448 | K37: 171373824 | L37: 4 | M37: 256 | N37: 3 | O37: stride | P37: 2 | Q37: 64 | R37: 8 | S37: 2.3402059 | T37: 0 | U37: flatten | V37: 0.084544721 | W37: 0.079128219 | X37: 1 | Y37: adam | Z37: 0.00024421795 | AA37: 4.8389842e-07 | AB37: step | AD37: none | AE37: =FALSE() -> FALSE
A38: B_uniform | B38: ccef3050 | C38: =FALSE() -> FALSE | D38: 0 | F38: 0 | G38: 0 | H38: =FALSE() -> FALSE | L38: 3 | M38: 256 | N38: 3 | O38: stride | P38: 2 | Q38: 64 | R38: 8 | S38: 2.2850354 | T38: 0 | U38: flatten | V38: 0.081593231 | W38: 0.063893499 | X38: 1 | Y38: adam | Z38: 0.00046200253 | AA38: 8.382442e-07 | AB38: step | AD38: bn | AE38: =TRUE() -> TRUE
A39: B_uniform | B39: b1e2b17a | C39: =TRUE() -> TRUE | D39: 1 | E39: 0.51136364 | F39: 1 | G39: 8 | H39: =TRUE() -> TRUE | I39: 32619 | J39: 307008 | K39: 10918976 | L39: 4 | M39: 32 | N39: 7 | O39: stride | P39: 2 | Q39: 64 | R39: 16 | S39: 2.2105621 | T39: 1 | U39: flatten | V39: 0.23429419 | W39: 0.19856942 | X39: 1 | Y39: adam | Z39: 0.00062306691 | AA39: 3.4512445e-08 | AB39: none | AD39: bn | AE39: =TRUE() -> TRUE
A40: B_uniform | B40: 2577bd0c | C40: =TRUE() -> TRUE | D40: 1 | E40: 0.73295455 | F40: 1 | G40: 24 | H40: =TRUE() -> TRUE | I40: 32619 | J40: 307008 | K40: 10918976 | L40: 4 | M40: 32 | N40: 7 | O40: stride | P40: 2 | Q40: 64 | R40: 16 | S40: 1.8937424 | T40: 1 | U40: flatten | V40: 0.23841574 | W40: 0.19822164 | X40: 1 | Y40: adam | Z40: 0.00075807672 | AA40: 3.1556292e-08 | AB40: none | AD40: bn | AE40: =TRUE() -> TRUE
...

Sheet Feasibility
A1: Feasibility drivers (RUN B, n=50) — chi-square + Cramer's V
A3: knob | B3: chi-square | C3: p | D3: q (FDR) | E3: Cramer's V | F3: feasible / total by level
A4: kernel_size | B4: 3.123 | C4: 0.20981403 | D4: 0.504 | E4: 0.25 | F4: 3.0:5/7 ; 5.0:18/22 ; 7.0:12/21
A5: channels | B5: 17.295 | C5: 0.00061467387 | D5: 0.0043 | E5: 0.588 | F5: 32.0:23/26 ; 64.0:6/7 ; 128.0:1/7 ; 256.0:5/10
A6: downsample_mode | B6: 0.344 | C6: 0.55765893 | D6: 0.7807 | E6: 0.083 | F6: pool:11/17 ; stride:24/33
A7: resize_to | B7: 0.066 | C7: 0.79704581 | D7: 0.81 | E7: 0.036 | F7: 32:13/18 ; 64:22/32
A8: depth | B8: 2.143 | C8: 0.54329125 | D8: 0.7807 | E8: 0.207 | F8: 2:14/20 ; 3:9/12 ; 4:8/10 ; 5:4/8
A9: fc_layers | B9: 0.964 | C9: 0.81002996 | D9: 0.81 | E9: 0.139 | F9: 0:19/28 ; 1:11/14 ; 2:4/6 ; 3:1/2
A10: T | B10: 1.531 | C10: 0.21602058 | D10: 0.504 | E10: 0.175 | F10: 8:8/14 ; 16:27/36
A13: Live check — feasibility rate by channels (formulas over 'Trial data')
A14: channels | B14: feasible | C14: total | D14: rate
A15: 32 | B15: =SUMIFS('Trial data'!$D$2:$D$66,'Trial data'!$A$2:$A$66,"B_uniform",'Trial data'!$M$2:$M$66,32) -> 23 | C15: =COUNTIFS('Trial data'!$A$2:$A$66,"B_uniform",'Trial data'!$M$2:$M$66,32) -> 26 | D15: =IF(C15=0,0,B15/C15) -> 0.88461538
A16: 64 | B16: =SUMIFS('Trial data'!$D$2:$D$66,'Trial data'!$A$2:$A$66,"B_uniform",'Trial data'!$M$2:$M$66,64) -> 6 | C16: =COUNTIFS('Trial data'!$A$2:$A$66,"B_uniform",'Trial data'!$M$2:$M$66,64) -> 7 | D16: =IF(C16=0,0,B16/C16) -> 0.85714286
A17: 128 | B17: =SUMIFS('Trial data'!$D$2:$D$66,'Trial data'!$A$2:$A$66,"B_uniform",'Trial data'!$M$2:$M$66,128) -> 1 | C17: =COUNTIFS('Trial data'!$A$2:$A$66,"B_uniform",'Trial data'!$M$2:$M$66,128) -> 7 | D17: =IF(C17=0,0,B17/C17) -> 0.14285714
A18: 256 | B18: =SUMIFS('Trial data'!$D$2:$D$66,'Trial data'!$A$2:$A$66,"B_uniform",'Trial data'!$M$2:$M$66,256) -> 5 | C18: =COUNTIFS('Trial data'!$A$2:$A$66,"B_uniform",'Trial data'!$M$2:$M$66,256) -> 10 | D18: =IF(C18=0,0,B18/C18) -> 0.5

Sheet Accuracy effects
A1: What moves accuracy (RUN B feasible, n=35) — nonparametric, FDR-corrected
A3: knob | B3: test | C3: statistic | D3: p | E3: q (FDR) | F3: effect size | G3: significant | H3: interpretation
A4: batchnorm | B4: Mann-Whitney | C4: 28.5 | D4: 0.0018878402 | E4: 0.0142 | F4: 0.736 | G4: yes | H4: BN on: median .76 vs .21. Decisive.
A5: tau | B5: Spearman | C5: -0.599 | D5: 0.00014528064 | E5: 0.0022 | F5: -0.599 | G5: yes | H5: lower tau better (rho -0.60).
A6: weight_decay | B6: Spearman | C6: -0.473 | D6: 0.0040848054 | E6: 0.0204 | F6: -0.473 | G6: yes | H6: lower wd better (rho -0.47).
A7: lr | B7: Spearman | C7: 0.409 | D7: 0.014577175 | E7: 0.0437 | F7: 0.409 | G7: yes | H7: higher lr (to 5e-3) better.
A8: optimizer | B8: Mann-Whitney | C8: 59.5 | D8: 0.11663101 | E8: 0.1749 | F8: 0.393 | G8: no | H8: adam~adamw (n.s.).
A9: fc_layers | B9: Kruskal-Wallis | C9: 8.735 | D9: 0.012680736 | E9: 0.0437 | F9: 0.217 | G9: yes | H9: 0 hidden FC best.
A10: depth | B10: Kruskal-Wallis | C10: 8.744 | D10: 0.032894966 | E10: 0.0822 | F10: 0.185 | G10: no | H10: shallow (2-3) better.
A11: label_smoothing | B11: Spearman | C11: 0.182 | D11: 0.29494083 | E11: 0.3687 | F11: 0.182 | G11: no | H11: n.s.
A12: kernel_size | B12: Kruskal-Wallis | C12: 6.253 | D12: 0.043881566 | E12: 0.094 | F12: 0.133 | G12: no | H12: k5-7 mild edge.
A13: scheduler | B13: Kruskal-Wallis | C13: 7.071 | D13: 0.069667949 | E13: 0.1306 | F13: 0.131 | G13: no | H13: weak.
A14: downsample_mode | B14: Mann-Whitney | C14: 142.5 | D14: 0.72200287 | E14: 0.722 | F14: 0.08 | G14: no | H14: n.s.
A15: dropout_rate | B15: Spearman | C15: -0.072 | D15: 0.68131022 | E15: 0.722 | F15: -0.072 | G15: no | H15: n.s.
... A18: resize_to | B18: Kruskal-Wallis | C18: 0.4 | D18: 0.52714043 | E18: 0.6082 | F18: -0.018 | G18: no | H18: n.s.

Sheet Normalization
A1: Headline result: normalization present vs absent (both runs pooled)
A3: Group | B3: n | C3: median best_val | D3: mean best_val
A4: Normalization ON | B4: 31 | C4: 0.733 | D4: 0.618
A5: Normalization OFF | B5: 10 | C5: 0.068 | D5: 0.28
A7: Mann-Whitney U=259.5, p=0.001524, rank-biserial r=0.674 (large effect).
A9: Learned (best_val > 1/11 chance) vs dead — 2x2 contingency:
B10: dead | C10: learned
A11: norm OFF | B11: 6 | C11: 4
A12: norm ON | B12: 2 | C12: 29
A14: Fisher's exact p=0.001061, odds ratio=21.8. A network without normalization is ~22x more likely to be dead.

Sheet Top configs
A1: Top configurations (feasible, by best_val) + accuracy-vs-size
A3: run | B3: trial_id | C3: best_val | D3: neurons | E3: params | F3: depth | G3: channels | H3: kernel_size | I3: T | J3: fc_layers | K3: norm_kind | L3: tau | M3: lr
A4: B_uniform | B4: 1a70b753 | C4: 0.875 | D4: 31531 | E4: 104128 | F4: 2 | G4: 32 | H4: 7 | I4: 16 | J4: 0 | K4: bn | L4: 1.6868134 | M4: 0.0029181265
A5: B_uniform | B5: 2449adcc | C5: 0.85795455 | D5: 34219 | E5: 86816 | F5: 2 | G5: 32 | H5: 5 | I5: 16 | J5: 0 | K5: bn | L5: 1.6876772 | M5: 0.00352234
A6: B_uniform | B6: 74c81148 | C6: 0.84659091 | D6: 34219 | E6: 86816 | F6: 2 | G6: 32 | H6: 5 | I6: 16 | J6: 0 | K6: bn | L6: 1.9687315 | M6: 0.0016311179
A7: B_uniform | B7: a6bfc11a | C7: 0.83522727 | D7: 31531 | E7: 104128 | F7: 2 | G7: 32 | H7: 7 | I7: 16 | J7: 0 | K7: bn | L7: 1.7017263 | M7: 0.0027842017
A8: B_uniform | B8: f4c87a09 | C8: 0.82954545 | D8: 81931 | E8: 150912 | F8: 2 | G8: 64 | H8: 5 | I8: 16 | J8: 0 | K8: bn | L8: 1.6837708 | M8: 0.0016061295
A9: B_uniform | B9: f07246e7 | C9: 0.82386364 | D9: 40971 | E9: 49856 | F9: 2 | G9: 32 | H9: 5 | I9: 16 | J9: 0 | K9: bn | L9: 1.6854887 | M9: 0.0032475717
A10: B_uniform | B10: f71edc30 | C10: 0.77840909 | D10: 32619 | E10: 307008 | F10: 4 | G10: 32 | H10: 7 | I10: 16 | J10: 1 | K10: bn | L10: 2.0782954 | M10: 0.00078790479
A11: B_uniform | B11: 3ebae440 | C11: 0.77840909 | D11: 31819 | E11: 106848 | F11: 3 | G11: 32 | H11: 7 | I11: 16 | J11: 0 | K11: bn | L11: 1.5216624 | M11: 0.0021338293
A12: B_uniform | B12: 7d05d575 | C12: 0.77272727 | D12: 32331 | E12: 256768 | F12: 3 | G12: 32 | H12: 7 | I12: 16 | J12: 1 | K12: bn | L12: 1.9354048 | M12: 0.0024596337
A13: B_uniform | B13: a3fbddc9 | C13: 0.77272727 | D13: 31819 | E13: 106848 | F13: 3 | G13: 32 | H13: 7 | I13: 16 | J13: 0 | K13: bn | L13: 1.5042649 | M13: 0.0022461979
